
# TestSprite AI Testing Report(MCP)

---

## 1️⃣ Document Metadata
- **Project Name:** create-anything-app
- **Date:** 2025-11-01
- **Prepared by:** TestSprite AI Team

---

## 2️⃣ Requirement Validation Summary

#### Test TC001
- **Test Name:** verify jwt token issuance and user info retrieval
- **Test Code:** [TC001_verify_jwt_token_issuance_and_user_info_retrieval.py](./TC001_verify_jwt_token_issuance_and_user_info_retrieval.py)
- **Test Error:** Traceback (most recent call last):
  File "/var/task/handler.py", line 258, in run_with_retry
    exec(code, exec_env)
  File "<string>", line 37, in <module>
  File "<string>", line 15, in test_verify_jwt_token_issuance_and_user_info_retrieval
AssertionError: Expected 401 Unauthorized for unauthenticated token request, got 200

- **Test Visualization and Result:** https://www.testsprite.com/dashboard/mcp/tests/bb244afe-ce6a-404c-9303-7083bce9db39/a045efaa-679b-421f-98da-db438de2753d
- **Status:** ❌ Failed
- **Analysis / Findings:** {{TODO:AI_ANALYSIS}}.
---

#### Test TC002
- **Test Name:** validate product creation with complete and valid data
- **Test Code:** [TC002_validate_product_creation_with_complete_and_valid_data.py](./TC002_validate_product_creation_with_complete_and_valid_data.py)
- **Test Error:** Traceback (most recent call last):
  File "<string>", line 12, in get_jwt_token
AssertionError: Expected JSON response from auth token endpoint, got Content-Type: text/html

During handling of the above exception, another exception occurred:

Traceback (most recent call last):
  File "/var/task/handler.py", line 258, in run_with_retry
    exec(code, exec_env)
  File "<string>", line 103, in <module>
  File "<string>", line 21, in test_validate_product_creation_with_complete_and_valid_data
  File "<string>", line 18, in get_jwt_token
Exception: Authentication failed: Expected JSON response from auth token endpoint, got Content-Type: text/html

- **Test Visualization and Result:** https://www.testsprite.com/dashboard/mcp/tests/bb244afe-ce6a-404c-9303-7083bce9db39/6636b962-b605-40d1-b84a-e22de99bc2a2
- **Status:** ❌ Failed
- **Analysis / Findings:** {{TODO:AI_ANALYSIS}}.
---

#### Test TC003
- **Test Name:** fetch products by valid company id
- **Test Code:** [TC003_fetch_products_by_valid_company_id.py](./TC003_fetch_products_by_valid_company_id.py)
- **Test Error:** Traceback (most recent call last):
  File "/var/task/handler.py", line 258, in run_with_retry
    exec(code, exec_env)
  File "<string>", line 69, in <module>
  File "<string>", line 12, in test_fetch_products_by_valid_company_id
AssertionError: Authentication failed with status code 404

- **Test Visualization and Result:** https://www.testsprite.com/dashboard/mcp/tests/bb244afe-ce6a-404c-9303-7083bce9db39/475e87ea-ccb8-4d25-8425-49eec0f8efe2
- **Status:** ❌ Failed
- **Analysis / Findings:** {{TODO:AI_ANALYSIS}}.
---

#### Test TC004
- **Test Name:** retrieve ai predictions with valid parameters
- **Test Code:** [TC004_retrieve_ai_predictions_with_valid_parameters.py](./TC004_retrieve_ai_predictions_with_valid_parameters.py)
- **Test Error:** Traceback (most recent call last):
  File "/var/task/requests/models.py", line 974, in json
    return complexjson.loads(self.text, **kwargs)
           ^^^^^^^^^^^^^^^^^^^^^^^^^^^^^^^^^^^^^^
  File "/var/lang/lib/python3.12/site-packages/simplejson/__init__.py", line 514, in loads
    return _default_decoder.decode(s)
           ^^^^^^^^^^^^^^^^^^^^^^^^^^
  File "/var/lang/lib/python3.12/site-packages/simplejson/decoder.py", line 386, in decode
    obj, end = self.raw_decode(s)
               ^^^^^^^^^^^^^^^^^^
  File "/var/lang/lib/python3.12/site-packages/simplejson/decoder.py", line 416, in raw_decode
    return self.scan_once(s, idx=_w(s, idx).end())
           ^^^^^^^^^^^^^^^^^^^^^^^^^^^^^^^^^^^^^^^
simplejson.errors.JSONDecodeError: Expecting value: line 2 column 1 (char 1)

During handling of the above exception, another exception occurred:

Traceback (most recent call last):
  File "<string>", line 12, in test_retrieve_ai_predictions_with_valid_parameters
  File "/var/task/requests/models.py", line 978, in json
    raise RequestsJSONDecodeError(e.msg, e.doc, e.pos)
requests.exceptions.JSONDecodeError: Expecting value: line 2 column 1 (char 1)

During handling of the above exception, another exception occurred:

Traceback (most recent call last):
  File "/var/task/handler.py", line 258, in run_with_retry
    exec(code, exec_env)
  File "<string>", line 53, in <module>
  File "<string>", line 18, in test_retrieve_ai_predictions_with_valid_parameters
Exception: Authentication failed: Expecting value: line 2 column 1 (char 1)

- **Test Visualization and Result:** https://www.testsprite.com/dashboard/mcp/tests/bb244afe-ce6a-404c-9303-7083bce9db39/eed79170-947f-4fb4-9b66-bd4a20976bd2
- **Status:** ❌ Failed
- **Analysis / Findings:** {{TODO:AI_ANALYSIS}}.
---

#### Test TC005
- **Test Name:** create ai prediction with required fields
- **Test Code:** [TC005_create_ai_prediction_with_required_fields.py](./TC005_create_ai_prediction_with_required_fields.py)
- **Test Error:** Traceback (most recent call last):
  File "/var/task/requests/models.py", line 974, in json
    return complexjson.loads(self.text, **kwargs)
           ^^^^^^^^^^^^^^^^^^^^^^^^^^^^^^^^^^^^^^
  File "/var/lang/lib/python3.12/site-packages/simplejson/__init__.py", line 514, in loads
    return _default_decoder.decode(s)
           ^^^^^^^^^^^^^^^^^^^^^^^^^^
  File "/var/lang/lib/python3.12/site-packages/simplejson/decoder.py", line 386, in decode
    obj, end = self.raw_decode(s)
               ^^^^^^^^^^^^^^^^^^
  File "/var/lang/lib/python3.12/site-packages/simplejson/decoder.py", line 416, in raw_decode
    return self.scan_once(s, idx=_w(s, idx).end())
           ^^^^^^^^^^^^^^^^^^^^^^^^^^^^^^^^^^^^^^^
simplejson.errors.JSONDecodeError: Expecting value: line 2 column 1 (char 1)

During handling of the above exception, another exception occurred:

Traceback (most recent call last):
  File "<string>", line 15, in test_create_ai_prediction_with_required_fields
  File "/var/task/requests/models.py", line 978, in json
    raise RequestsJSONDecodeError(e.msg, e.doc, e.pos)
requests.exceptions.JSONDecodeError: Expecting value: line 2 column 1 (char 1)

During handling of the above exception, another exception occurred:

Traceback (most recent call last):
  File "<string>", line 17, in test_create_ai_prediction_with_required_fields
AssertionError: Authentication response is not valid JSON: Expecting value: line 2 column 1 (char 1)

During handling of the above exception, another exception occurred:

Traceback (most recent call last):
  File "/var/task/handler.py", line 258, in run_with_retry
    exec(code, exec_env)
  File "<string>", line 93, in <module>
  File "<string>", line 23, in test_create_ai_prediction_with_required_fields
AssertionError: Authentication step failed: Authentication response is not valid JSON: Expecting value: line 2 column 1 (char 1)

- **Test Visualization and Result:** https://www.testsprite.com/dashboard/mcp/tests/bb244afe-ce6a-404c-9303-7083bce9db39/5e9bf84c-89f4-46a8-8c58-8e55a682b483
- **Status:** ❌ Failed
- **Analysis / Findings:** {{TODO:AI_ANALYSIS}}.
---

#### Test TC006
- **Test Name:** get market reports for a company
- **Test Code:** [TC006_get_market_reports_for_a_company.py](./TC006_get_market_reports_for_a_company.py)
- **Test Error:** Traceback (most recent call last):
  File "/var/task/requests/models.py", line 974, in json
    return complexjson.loads(self.text, **kwargs)
           ^^^^^^^^^^^^^^^^^^^^^^^^^^^^^^^^^^^^^^
  File "/var/lang/lib/python3.12/site-packages/simplejson/__init__.py", line 514, in loads
    return _default_decoder.decode(s)
           ^^^^^^^^^^^^^^^^^^^^^^^^^^
  File "/var/lang/lib/python3.12/site-packages/simplejson/decoder.py", line 386, in decode
    obj, end = self.raw_decode(s)
               ^^^^^^^^^^^^^^^^^^
  File "/var/lang/lib/python3.12/site-packages/simplejson/decoder.py", line 416, in raw_decode
    return self.scan_once(s, idx=_w(s, idx).end())
           ^^^^^^^^^^^^^^^^^^^^^^^^^^^^^^^^^^^^^^^
simplejson.errors.JSONDecodeError: Expecting value: line 2 column 1 (char 1)

During handling of the above exception, another exception occurred:

Traceback (most recent call last):
  File "<string>", line 12, in get_jwt_token
  File "/var/task/requests/models.py", line 978, in json
    raise RequestsJSONDecodeError(e.msg, e.doc, e.pos)
requests.exceptions.JSONDecodeError: Expecting value: line 2 column 1 (char 1)

During handling of the above exception, another exception occurred:

Traceback (most recent call last):
  File "<string>", line 14, in get_jwt_token
AssertionError: Response content is not valid JSON

During handling of the above exception, another exception occurred:

Traceback (most recent call last):
  File "/var/task/handler.py", line 258, in run_with_retry
    exec(code, exec_env)
  File "<string>", line 58, in <module>
  File "<string>", line 29, in test_get_market_reports_for_company
  File "<string>", line 26, in get_jwt_token
RuntimeError: Failed to obtain JWT token: Response content is not valid JSON

- **Test Visualization and Result:** https://www.testsprite.com/dashboard/mcp/tests/bb244afe-ce6a-404c-9303-7083bce9db39/88a9f641-ca6e-4d68-b389-06ea56b30736
- **Status:** ❌ Failed
- **Analysis / Findings:** {{TODO:AI_ANALYSIS}}.
---

#### Test TC007
- **Test Name:** fetch target markets successfully
- **Test Code:** [TC007_fetch_target_markets_successfully.py](./TC007_fetch_target_markets_successfully.py)
- **Test Error:** Traceback (most recent call last):
  File "/var/task/requests/models.py", line 974, in json
    return complexjson.loads(self.text, **kwargs)
           ^^^^^^^^^^^^^^^^^^^^^^^^^^^^^^^^^^^^^^
  File "/var/lang/lib/python3.12/site-packages/simplejson/__init__.py", line 514, in loads
    return _default_decoder.decode(s)
           ^^^^^^^^^^^^^^^^^^^^^^^^^^
  File "/var/lang/lib/python3.12/site-packages/simplejson/decoder.py", line 386, in decode
    obj, end = self.raw_decode(s)
               ^^^^^^^^^^^^^^^^^^
  File "/var/lang/lib/python3.12/site-packages/simplejson/decoder.py", line 416, in raw_decode
    return self.scan_once(s, idx=_w(s, idx).end())
           ^^^^^^^^^^^^^^^^^^^^^^^^^^^^^^^^^^^^^^^
simplejson.errors.JSONDecodeError: Expecting value: line 2 column 1 (char 1)

During handling of the above exception, another exception occurred:

Traceback (most recent call last):
  File "<string>", line 11, in get_jwt_token
  File "/var/task/requests/models.py", line 978, in json
    raise RequestsJSONDecodeError(e.msg, e.doc, e.pos)
requests.exceptions.JSONDecodeError: Expecting value: line 2 column 1 (char 1)

During handling of the above exception, another exception occurred:

Traceback (most recent call last):
  File "/var/task/handler.py", line 258, in run_with_retry
    exec(code, exec_env)
  File "<string>", line 46, in <module>
  File "<string>", line 23, in test_fetch_target_markets_successfully
  File "<string>", line 20, in get_jwt_token
Exception: Failed to get JWT token: Expecting value: line 2 column 1 (char 1)

- **Test Visualization and Result:** https://www.testsprite.com/dashboard/mcp/tests/bb244afe-ce6a-404c-9303-7083bce9db39/0c243592-b758-439c-a9ca-c0747a23ffe5
- **Status:** ❌ Failed
- **Analysis / Findings:** {{TODO:AI_ANALYSIS}}.
---

#### Test TC008
- **Test Name:** retrieve risk assessments
- **Test Code:** [TC008_retrieve_risk_assessments.py](./TC008_retrieve_risk_assessments.py)
- **Test Error:** Traceback (most recent call last):
  File "/var/task/handler.py", line 258, in run_with_retry
    exec(code, exec_env)
  File "<string>", line 24, in <module>
  File "<string>", line 14, in test_retrieve_risk_assessments
AssertionError: Expected status code 200, got 404

- **Test Visualization and Result:** https://www.testsprite.com/dashboard/mcp/tests/bb244afe-ce6a-404c-9303-7083bce9db39/fb769753-e4c8-43c1-9113-5638c8d1f975
- **Status:** ❌ Failed
- **Analysis / Findings:** {{TODO:AI_ANALYSIS}}.
---

#### Test TC009
- **Test Name:** get price optimization recommendations
- **Test Code:** [TC009_get_price_optimization_recommendations.py](./TC009_get_price_optimization_recommendations.py)
- **Test Error:** Traceback (most recent call last):
  File "/var/task/requests/models.py", line 974, in json
    return complexjson.loads(self.text, **kwargs)
           ^^^^^^^^^^^^^^^^^^^^^^^^^^^^^^^^^^^^^^
  File "/var/lang/lib/python3.12/site-packages/simplejson/__init__.py", line 514, in loads
    return _default_decoder.decode(s)
           ^^^^^^^^^^^^^^^^^^^^^^^^^^
  File "/var/lang/lib/python3.12/site-packages/simplejson/decoder.py", line 386, in decode
    obj, end = self.raw_decode(s)
               ^^^^^^^^^^^^^^^^^^
  File "/var/lang/lib/python3.12/site-packages/simplejson/decoder.py", line 416, in raw_decode
    return self.scan_once(s, idx=_w(s, idx).end())
           ^^^^^^^^^^^^^^^^^^^^^^^^^^^^^^^^^^^^^^^
simplejson.errors.JSONDecodeError: Expecting value: line 2 column 1 (char 1)

During handling of the above exception, another exception occurred:

Traceback (most recent call last):
  File "<string>", line 23, in test_get_price_optimization_recommendations
  File "/var/task/requests/models.py", line 978, in json
    raise RequestsJSONDecodeError(e.msg, e.doc, e.pos)
requests.exceptions.JSONDecodeError: Expecting value: line 2 column 1 (char 1)

During handling of the above exception, another exception occurred:

Traceback (most recent call last):
  File "/var/task/handler.py", line 258, in run_with_retry
    exec(code, exec_env)
  File "<string>", line 31, in <module>
  File "<string>", line 25, in test_get_price_optimization_recommendations
AssertionError: Response is not valid JSON

- **Test Visualization and Result:** https://www.testsprite.com/dashboard/mcp/tests/bb244afe-ce6a-404c-9303-7083bce9db39/520ee8ec-41ea-454b-9ae6-c995979619c6
- **Status:** ❌ Failed
- **Analysis / Findings:** {{TODO:AI_ANALYSIS}}.
---

#### Test TC010
- **Test Name:** fetch market trends data
- **Test Code:** [TC010_fetch_market_trends_data.py](./TC010_fetch_market_trends_data.py)
- **Test Error:** Traceback (most recent call last):
  File "/var/task/handler.py", line 258, in run_with_retry
    exec(code, exec_env)
  File "<string>", line 24, in <module>
  File "<string>", line 14, in test_fetch_market_trends_data
AssertionError: Expected status 200, got 404

- **Test Visualization and Result:** https://www.testsprite.com/dashboard/mcp/tests/bb244afe-ce6a-404c-9303-7083bce9db39/5cf7659f-5716-482f-9b6a-657cb5cceeea
- **Status:** ❌ Failed
- **Analysis / Findings:** {{TODO:AI_ANALYSIS}}.
---


## 3️⃣ Coverage & Matching Metrics

- **0.00** of tests passed

| Requirement        | Total Tests | ✅ Passed | ❌ Failed  |
|--------------------|-------------|-----------|------------|
| ...                | ...         | ...       | ...        |
---


## 4️⃣ Key Gaps / Risks
{AI_GNERATED_KET_GAPS_AND_RISKS}
---